#VRML_SIM R2019a utf8
WorldInfo {
}
Viewpoint {
  orientation -0.024531586579019674 -0.9995402410561032 0.017818747695138016 4.73756179094143
  position 1.0295243946824952 0.1932283983779914 0.09006276315421155
}
TexturedBackground {
}
TexturedBackgroundLight {
}
Floor {
}
Solid {
  translation 0 0.25 0
  children [
    Shape {
      appearance PBRAppearance {
        baseColor 0.4470588235294118 0.6235294117647059 0.8117647058823529
        roughness 1
        metalness 0
      }
      geometry Cylinder {
        height 0.5
        radius 0.05
      }
    }
    HingeJoint {
      jointParameters HingeJointParameters {
        axis 0 1 0
        anchor 0 0.255 0
        minStop -0.7854
        maxStop 0.7854
        springConstant 3
        dampingConstant 2
        staticFriction 0.1
      }
      endPoint Solid {
        translation 0 0.25496863907334466 0
        children [
          Shape {
            appearance PBRAppearance {
              baseColor 0.9372549019607843 0.1607843137254902 0.1607843137254902
              roughness 1
              metalness 0
            }
            geometry Box {
              size 0.8 0.01 0.1
            }
          }
        ]
        physics Physics {
        }
      }
    }
    HingeJoint {
      jointParameters HingeJointParameters {
        axis 0 1 0
      }
      endPoint Solid {
        translation 0 0 0.055000000036147495
        children [
          Shape {
            appearance PBRAppearance {
              baseColor 0.9372549019607843 0.1607843137254902 0.1607843137254902
              metalness 0
            }
            geometry Box {
              size 0.1 0.03 0.01
            }
          }
        ]
        name "solid(1)"
        physics Physics {
        }
      }
    }
  ]
}
